File: KEN004_Speglun.xrdml
<?xml version="1.0" encoding="UTF-8"?>
<xrdMeasurements xmlns="http://www.xrdml.com/XRDMeasurement/1.5" xmlns:xsi="http://www.w3.org/2001/XMLSchema-instance" xsi:schemaLocation="http://www.xrdml.com/XRDMeasurement/1.5 http://www.xrdml.com/XRDMeasurement/1.5/XRDMeasurement.xsd" status="Completed">
	<comment>
		<entry>Configuration=MRD 2016, Owner=hydrogen, Creation date=09-Dec-16 19:44:12</entry>
		<entry>Goniometer=PW3050/65 (Theta/2Theta); Minimum step size 2Theta:0.001; Minimum step size Omega:0.001</entry>
		<entry>Sample stage=MRD Cradle; Minimum step size Phi:0.01; Minimum step size Chi:0.01; Minimum step size X:0.01; Minimum step size Y:0.01; Minimum step size Z:0.001</entry>
		<entry>Diffractometer system=XPERT-PRO</entry>
		<entry>Measurement program=Manual, Owner=hydrogen, Creation date=31-Jan-19 12:02:40</entry>
		<entry>Fine Calibration Offset for 2Theta = 0.008 deg</entry>
		<entry>Fine Calibration Offset for Omega = -0.180 deg</entry>
	</comment>
	<sample type="To be analyzed">
		<id></id>
		<name></name>
		<preparedBy></preparedBy>
	</sample>
	<xrdMeasurement measurementType="Scan" status="Completed" sampleMode="Reflection">
		<comment>
			<entry>PHD Lower Level = 5.63 (keV), PHD Upper Level = 12.88 (keV)</entry>
		</comment>
		<usedWavelength intended="K-Alpha 1">
			<kAlpha1 unit="Angstrom">1.5405940</kAlpha1>
			<kAlpha2 unit="Angstrom">1.5444080</kAlpha2>
			<kBeta unit="Angstrom">1.3922500</kBeta>
			<ratioKAlpha2KAlpha1>0.5200</ratioKAlpha2KAlpha1>
		</usedWavelength>
		<incidentBeamPath>
			<radius unit="mm">320.00</radius>
			<xRayTube id="1010048" name="Empyrean Cu LFF HR (9430 033 7310x) DK164548">
				<tension unit="kV">45</tension>
				<current unit="mA">40</current>
				<anodeMaterial>Cu</anodeMaterial>
				<focus type="Line">
					<length unit="mm">12.0</length>
					<width unit="mm">0.4</width>
					<takeOffAngle unit="deg">3.5</takeOffAngle>
				</focus>
			</xRayTube>
			<xRayMirror id="27090001" name="Inc. Beam Cu W/Si (hybrid MRD)" hybrid="true">
				<crystal type="Graded" shape="Parabolic">W/Si</crystal>
				<acceptanceAngle unit="deg">0.800</acceptanceAngle>
				<length unit="mm">60.0</length>
			</xRayMirror>
			<monochromator id="23090002" name="Hybrid monochr. 2xGe(220) for Cu" hybrid="true">
				<crystal type="Asymmetric" shape="Flat">Ge</crystal>
				<numberOfReflections>2</numberOfReflections>
				<hkl>
					<h>2</h>
					<k>2</k>
					<l>0</l>
				</hkl>
			</monochromator>
			<divergenceSlit id="22010007" name="Fixed slit 1/8°" xsi:type="fixedDivergenceSlitType">
				<distanceToSample unit="mm">220.00</distanceToSample>
				<height unit="mm">0.19</height>
			</divergenceSlit>
			<beamAttenuator id="26010002" name="Beam attenuator Cu 0.1 mm" xsi:type="intensitySwitchedBeamAttenuatorType">
				<factor>119.20</factor>
				<material>Cu</material>
				<activateLevel unit="counts per second">800000</activateLevel>
				<deactivateLevel unit="counts per second">300000</deactivateLevel>
			</beamAttenuator>
		</incidentBeamPath>
		<sampleOffset>
			<position axis="2Theta" unit="deg">0.000</position>
			<position axis="Omega" unit="deg">0.455</position>
		</sampleOffset>
		<diffractedBeamPath>
			<radius unit="mm">320.00</radius>
			<parallelPlateCollimator id="25010001" name="Parallel plate collimator 0.27°">
				<opening unit="deg">0.27</opening>
			</parallelPlateCollimator>
			<receivingSlit id="22070001" name="Parallel plate collimator slit">
				<height unit="mm">0.10</height>
			</receivingSlit>
			<detector id="7010011" name="Proportional detector Xe" xsi:type="pointDetectorType">
				<phd>
					<lowerLevel unit="%">35.0</lowerLevel>
					<upperLevel unit="%">80.0</upperLevel>
				</phd>
			</detector>
		</diffractedBeamPath>
		<scan appendNumber="0" mode="Continuous" scanAxis="2Theta-Omega" status="Completed">
			<header>
				<startTimeStamp>2019-01-31T15:04:14+00:00</startTimeStamp>
				<endTimeStamp>2019-01-31T15:10:42+00:00</endTimeStamp>
				<author>
					<name>X-ray User</name>
				</author>
				<source>
					<applicationSoftware version="5.2a">Data Collector</applicationSoftware>
					<instrumentControlSoftware version="2.2B 20140619">XPERT-PRO</instrumentControlSoftware>
					<instrumentID>0000000011014754</instrumentID>
				</source>
			</header>
			<scanAxisCenter>
				<position axis="2Theta" unit="deg">2.500</position>
				<position axis="Omega" unit="deg">1.250</position>
			</scanAxisCenter>
			<reflection>
				<hkl>
					<h>0</h>
					<k>0</k>
					<l>0</l>
				</hkl>
			</reflection>
			<dataPoints>
				<positions axis="2Theta" unit="deg">
					<startPosition>0.010</startPosition>
					<endPosition>4.990</endPosition>
				</positions>
				<positions axis="Omega" unit="deg">
					<startPosition>0.0050</startPosition>
					<endPosition>2.4950</endPosition>
				</positions>
				<positions axis="Phi" unit="deg">
					<commonPosition>0.00</commonPosition>
				</positions>
				<positions axis="Chi" unit="deg">
					<commonPosition>0.00</commonPosition>
				</positions>
				<positions axis="X" unit="mm">
					<commonPosition>0.00</commonPosition>
				</positions>
				<positions axis="Y" unit="mm">
					<commonPosition>0.00</commonPosition>
				</positions>
				<positions axis="Z" unit="mm">
					<commonPosition>6.857</commonPosition>
				</positions>
				<beamAttenuationFactors>119.20 119.20 119.20 119.20 119.20 119.20 119.20 1.00 1.00 1.00 1.00 1.00 1.00 1.00 1.00 1.00 1.00 1.00 1.00 1.00 1.00 1.00 1.00 1.00 1.00 1.00 1.00 1.00 1.00 1.00 1.00 1.00 1.00 119.20 119.20 119.20 119.20 119.20 119.20 119.20 119.20 119.20 119.20 119.20 119.20 119.20 119.20 119.20 119.20 119.20 119.20 119.20 119.20 119.20 119.20 119.20 119.20 119.20 119.20 119.20 119.20 119.20 119.20 119.20 119.20 119.20 119.20 119.20 119.20 119.20 119.20 119.20 119.20 119.20 119.20 119.20 119.20 119.20 119.20 119.20 119.20 119.20 119.20 119.20 119.20 119.20 119.20 119.20 119.20 119.20 119.20 119.20 119.20 119.20 119.20 119.20 119.20 119.20 119.20 1.00 1.00 1.00 1.00 1.00 1.00 1.00 1.00 1.00 1.00 1.00 1.00 1.00 1.00 1.00 1.00 1.00 1.00 1.00 1.00 1.00 1.00 1.00 1.00 1.00 1.00 1.00 1.00 1.00 1.00 1.00 1.00 1.00 1.00 1.00 1.00 1.00 1.00 1.00 1.00 1.00 1.00 1.00 1.00 1.00 1.00 1.00 1.00 1.00 1.00 1.00 1.00 1.00 1.00 1.00 1.00 1.00 1.00 1.00 1.00 1.00 1.00 1.00 1.00 1.00 1.00 1.00 1.00 1.00 1.00 1.00 1.00 1.00 1.00 1.00 1.00 1.00 1.00 1.00 1.00 1.00 1.00 1.00 1.00 1.00 1.00 1.00 1.00 1.00 1.00 1.00 1.00 1.00 1.00 1.00 1.00 1.00 1.00 1.00 1.00 1.00 1.00 1.00 1.00 1.00 1.00 1.00 1.00 1.00 1.00 1.00 1.00 1.00 1.00 1.00 1.00 1.00 1.00 1.00 1.00 1.00 1.00 1.00 1.00 1.00 1.00 1.00 1.00 1.00 1.00 1.00 1.00 1.00 1.00 1.00 1.00 1.00 1.00 1.00 1.00 1.00 1.00 1.00 1.00 1.00 1.00 1.00 1.00 1.00 1.00 1.00 1.00 1.00 1.00 1.00 1.00 1.00 1.00 1.00 1.00 1.00 1.00 1.00 1.00 1.00 1.00 1.00 1.00 1.00 1.00 1.00 1.00 1.00 1.00 1.00 1.00 1.00 1.00 1.00 1.00 1.00 1.00 1.00 1.00 1.00 1.00 1.00 1.00 1.00 1.00 1.00 1.00 1.00 1.00 1.00 1.00 1.00 1.00 1.00 1.00 1.00 1.00 1.00 1.00 1.00 1.00 1.00 1.00 1.00 1.00 1.00 1.00 1.00 1.00 1.00 1.00 1.00 1.00 1.00 1.00 1.00 1.00 1.00 1.00 1.00 1.00 1.00 1.00 1.00 1.00 1.00 1.00 1.00 1.00 1.00 1.00 1.00 1.00 1.00 1.00 1.00 1.00 1.00 1.00 1.00 1.00 1.00 1.00 1.00 1.00 1.00 1.00 1.00 1.00 1.00 1.00 1.00 1.00 1.00 1.00 1.00 1.00 1.00 1.00 1.00 1.00 1.00 1.00 1.00 1.00 1.00 1.00 1.00 1.00 1.00 1.00 1.00 1.00 1.00 1.00 1.00 1.00 1.00 1.00 1.00 1.00 1.00 1.00 1.00 1.00 1.00 1.00 1.00 1.00 1.00 1.00 1.00 1.00 1.00 1.00 1.00 1.00 1.00 1.00 1.00 1.00 1.00 1.00 1.00 1.00 1.00 1.00 1.00 1.00 1.00 1.00 1.00 1.00 1.00 1.00 1.00 1.00 1.00 1.00 1.00 1.00 1.00 1.00 1.00 1.00 1.00 1.00 1.00 1.00 1.00 1.00 1.00 1.00 1.00 1.00 1.00 1.00 1.00 1.00 1.00 1.00 1.00 1.00 1.00 1.00 1.00 1.00 1.00 1.00 1.00 1.00 1.00 1.00 1.00 1.00 1.00 1.00 1.00 1.00 1.00 1.00 1.00 1.00 1.00 1.00 1.00 1.00 1.00 1.00 1.00 1.00 1.00 1.00 1.00 1.00 1.00 1.00 1.00 1.00 1.00 1.00 1.00 1.00 1.00 1.00 1.00 1.00 1.00 1.00 1.00 1.00 1.00 1.00 1.00 1.00</beamAttenuationFactors>
				<commonCountingTime unit="seconds">0.60</commonCountingTime>
				<intensities unit="counts">8022518 9501670 8444247 6131529 3272755 1291174 419346 191634 150403 146293 153623 164187 178339 192493 207477 222782 237988 254165 269120 285733 299910 316108 331224 346306 363392 376365 392035 408079 421236 435710 449569 465247 478825 423398 433173 459754 478707 479422 480614 496468 510295 524242 534135 548797 548201 564174 570372 576332 598503 590994 622462 621151 632237 641058 658103 660845 687307 675506 700777 698512 711386 731650 716154 708644 730458 717822 745715 750722 741066 769913 767171 769555 776588 761807 792799 763238 766694 764668 762046 761688 747503 764430 763595 736656 727478 713531 712578 675387 649044 605059 569418 533420 461066 417915 378222 310158 266054 229341 208481 209873 182856 160040 143660 131054 119186 107687 94992 83734 75831 72809 71387 68145 63222 54811 46687 41512 39803 41219 42923 42743 40365 34926 28722 24037 22122 23109 25806 27956 28530 27115 22911 18379 14652 12729 13349 15731 18390 20053 20259 18559 15054 11549 8873 7419 8084 9949 12324 14151 14847 13909 12028 9018 6533 5005 4557 5344 7009 9001 10710 10955 10134 8445 6391 4446 3151 2815 3510 4837 6376 7873 8232 8005 6916 5220 3573 2301 1895 2083 3043 4281 5668 6417 6539 5943 4857 3269 2142 1393 1276 1784 2828 3753 4819 5344 5200 4591 3583 2410 1557 947 935 1348 2028 2957 3599 4135 3940 3643 2897 1952 1171 695 619 809 1402 2074 2574 3038 2996 2865 2287 1701 1080 614 398 502 905 1429 1850 2334 2458 2349 2015 1438 959 527 355 370 601 986 1446 1791 1973 1982 1724 1315 914 598 374 258 360 552 884 1123 1379 1516 1473 1254 946 621 368 231 222 314 520 729 1010 1102 1173 1082 843 667 460 282 172 196 305 458 690 829 913 942 873 752 522 383 210 193 186 307 470 596 734 797 825 748 615 431 271 202 138 183 267 378 513 577 642 572 584 441 365 261 178 147 156 227 294 388 442 497 484 415 370 285 237 152 127 139 178 240 313 380 439 414 380 328 253 177 155 107 125 190 221 279 332 348 336 309 286 216 184 121 128 106 128 192 205 269 283 290 259 259 197 151 129 116 111 118 150 175 191 229 257 244 211 183 138 123 99 118 106 142 152 186 224 245 207 181 182 164 128 108 96 88 133 154 160 165 195 194 189 170 142 108 95 91 87 91 136 128 159 153 147 166 122 118 99 93 85 77 80 111 94 118 141 113 135 107 111 89 79 54 63 76 80 107 105 141 113 120 125 96 109 90 58 61 54 58 91 75 100 101 86 84 87 71 59 54 54 60 60 73 70 108 68 89 68 85 67 57 60 54 46 65 53 43 53 71 73 60 71 56 64 48 53 52 54 54 59 66 72 68 71 71 52 59 68 45 46</intensities>
			</dataPoints>
		</scan>
	</xrdMeasurement>
</xrdMeasurements>