File: KEN004_vixl.xrdml
<?xml version="1.0" encoding="UTF-8"?>
<xrdMeasurements xmlns="http://www.xrdml.com/XRDMeasurement/1.5" xmlns:xsi="http://www.w3.org/2001/XMLSchema-instance" xsi:schemaLocation="http://www.xrdml.com/XRDMeasurement/1.5 http://www.xrdml.com/XRDMeasurement/1.5/XRDMeasurement.xsd" status="Not finished">
	<comment>
		<entry>Configuration=MRD 2016, Owner=hydrogen, Creation date=09-Dec-16 19:44:12</entry>
		<entry>Goniometer=PW3050/65 (Theta/2Theta); Minimum step size 2Theta:0.001; Minimum step size Omega:0.001</entry>
		<entry>Sample stage=MRD Cradle; Minimum step size Phi:0.01; Minimum step size Chi:0.01; Minimum step size X:0.01; Minimum step size Y:0.01; Minimum step size Z:0.001</entry>
		<entry>Diffractometer system=XPERT-PRO</entry>
		<entry>Measurement program=Manual, Owner=hydrogen, Creation date=24-Jan-19 13:50:59</entry>
		<entry>Fine Calibration Offset for 2Theta = 0.007 deg</entry>
		<entry>Fine Calibration Offset for Omega = -0.180 deg</entry>
	</comment>
	<sample type="To be analyzed">
		<id></id>
		<name></name>
		<preparedBy></preparedBy>
	</sample>
	<xrdMeasurement measurementType="Scan" status="Not finished" sampleMode="Reflection">
		<comment>
			<entry>PHD Lower Level = 5.63 (keV), PHD Upper Level = 12.88 (keV)</entry>
		</comment>
		<usedWavelength intended="K-Alpha 1">
			<kAlpha1 unit="Angstrom">1.5405940</kAlpha1>
			<kAlpha2 unit="Angstrom">1.5444080</kAlpha2>
			<kBeta unit="Angstrom">1.3922500</kBeta>
			<ratioKAlpha2KAlpha1>0.5200</ratioKAlpha2KAlpha1>
		</usedWavelength>
		<incidentBeamPath>
			<radius unit="mm">320.00</radius>
			<xRayTube id="1010048" name="Empyrean Cu LFF HR (9430 033 7310x) DK164548">
				<tension unit="kV">45</tension>
				<current unit="mA">40</current>
				<anodeMaterial>Cu</anodeMaterial>
				<focus type="Line">
					<length unit="mm">12.0</length>
					<width unit="mm">0.4</width>
					<takeOffAngle unit="deg">3.5</takeOffAngle>
				</focus>
			</xRayTube>
			<xRayMirror id="27090001" name="Inc. Beam Cu W/Si (hybrid MRD)" hybrid="true">
				<crystal type="Graded" shape="Parabolic">W/Si</crystal>
				<acceptanceAngle unit="deg">0.800</acceptanceAngle>
				<length unit="mm">60.0</length>
			</xRayMirror>
			<monochromator id="23090002" name="Hybrid monochr. 2xGe(220) for Cu" hybrid="true">
				<crystal type="Asymmetric" shape="Flat">Ge</crystal>
				<numberOfReflections>2</numberOfReflections>
				<hkl>
					<h>2</h>
					<k>2</k>
					<l>0</l>
				</hkl>
			</monochromator>
			<divergenceSlit id="22010007" name="Fixed slit 1/8°" xsi:type="fixedDivergenceSlitType">
				<distanceToSample unit="mm">220.00</distanceToSample>
				<height unit="mm">0.19</height>
			</divergenceSlit>
			<beamAttenuator id="26010002" name="Beam attenuator Cu 0.1 mm" xsi:type="intensitySwitchedBeamAttenuatorType">
				<factor>119.20</factor>
				<material>Cu</material>
				<activateLevel unit="counts per second">900000</activateLevel>
				<deactivateLevel unit="counts per second">800000</deactivateLevel>
			</beamAttenuator>
		</incidentBeamPath>
		<sampleOffset>
			<position axis="2Theta" unit="deg">0.000</position>
			<position axis="Omega" unit="deg">0.105</position>
		</sampleOffset>
		<diffractedBeamPath>
			<radius unit="mm">320.00</radius>
			<parallelPlateCollimator id="25010001" name="Parallel plate collimator 0.27°">
				<opening unit="deg">0.27</opening>
			</parallelPlateCollimator>
			<receivingSlit id="22070001" name="Parallel plate collimator slit">
				<height unit="mm">0.10</height>
			</receivingSlit>
			<detector id="7010011" name="Proportional detector Xe" xsi:type="pointDetectorType">
				<phd>
					<lowerLevel unit="%">35.0</lowerLevel>
					<upperLevel unit="%">80.0</upperLevel>
				</phd>
			</detector>
		</diffractedBeamPath>
		<scan appendNumber="0" mode="Continuous" scanAxis="2Theta-Omega" status="Not finished">
			<header>
				<startTimeStamp>2019-01-24T14:21:43+00:00</startTimeStamp>
				<endTimeStamp>2019-01-24T14:43:11+00:00</endTimeStamp>
				<author>
					<name>X-ray User</name>
				</author>
				<source>
					<applicationSoftware version="5.2a">Data Collector</applicationSoftware>
					<instrumentControlSoftware version="2.2B 20140619">XPERT-PRO</instrumentControlSoftware>
					<instrumentID>0000000011014754</instrumentID>
				</source>
			</header>
			<scanAxisCenter>
				<position axis="2Theta" unit="deg">55.000</position>
				<position axis="Omega" unit="deg">27.500</position>
			</scanAxisCenter>
			<reflection>
				<hkl>
					<h>0</h>
					<k>0</k>
					<l>0</l>
				</hkl>
			</reflection>
			<dataPoints>
				<positions axis="2Theta" unit="deg">
					<startPosition>35.020</startPosition>
					<endPosition>74.980</endPosition>
				</positions>
				<positions axis="Omega" unit="deg">
					<startPosition>17.5100</startPosition>
					<endPosition>37.4900</endPosition>
				</positions>
				<positions axis="Phi" unit="deg">
					<commonPosition>0.00</commonPosition>
				</positions>
				<positions axis="Chi" unit="deg">
					<commonPosition>0.00</commonPosition>
				</positions>
				<positions axis="X" unit="mm">
					<commonPosition>0.00</commonPosition>
				</positions>
				<positions axis="Y" unit="mm">
					<commonPosition>0.00</commonPosition>
				</positions>
				<positions axis="Z" unit="mm">
					<commonPosition>6.843</commonPosition>
				</positions>
				<beamAttenuationFactors>1.00 1.00 1.00 1.00 1.00 1.00 1.00 1.00 1.00 1.00 1.00 1.00 1.00 1.00 1.00 1.00 1.00 1.00 1.00 1.00 1.00 1.00 1.00 1.00 1.00 1.00 1.00 1.00 1.00 1.00 1.00 1.00 1.00 1.00 1.00 1.00 1.00 1.00 1.00 1.00 1.00 1.00 1.00 1.00 1.00 1.00 1.00 1.00 1.00 1.00 1.00 1.00 1.00 1.00 1.00 1.00 1.00 1.00 1.00 1.00 1.00 1.00 1.00 1.00 1.00 1.00 1.00 1.00 1.00 1.00 1.00 1.00 1.00 1.00 1.00 1.00 1.00 1.00 1.00 1.00 1.00 1.00 1.00 1.00 1.00 1.00 1.00 1.00 1.00 1.00 1.00 1.00 1.00 1.00 1.00 1.00 1.00 1.00 1.00 1.00 1.00 1.00 1.00 1.00 1.00 1.00 1.00 1.00 1.00 1.00 1.00 1.00 1.00 1.00 1.00 1.00 1.00 1.00 1.00 1.00 1.00 1.00 1.00 1.00 1.00 1.00 1.00 1.00 1.00 1.00 1.00 1.00 1.00 1.00 1.00 1.00 1.00 1.00 1.00 1.00 1.00 1.00 1.00 1.00 1.00 1.00 1.00 1.00 1.00 1.00 1.00 1.00 1.00 1.00 1.00 1.00 1.00 1.00 1.00 1.00 1.00 1.00 1.00 1.00 1.00 1.00 1.00 1.00 1.00 1.00 1.00 1.00 1.00 1.00 1.00 1.00 1.00 1.00 1.00 1.00 1.00 1.00 1.00 1.00 1.00 1.00 1.00 1.00 1.00 1.00 1.00 1.00 1.00 1.00 1.00 1.00 1.00 1.00 1.00 1.00 1.00 1.00 1.00 1.00 1.00 1.00 1.00 1.00 1.00 1.00 1.00 1.00 1.00 1.00 1.00 1.00 1.00 1.00 1.00 1.00 1.00 1.00 1.00 1.00 1.00 1.00 1.00 1.00 1.00 1.00 1.00 1.00 1.00 1.00 1.00 1.00 1.00 1.00 1.00 1.00 1.00 1.00 1.00 1.00 1.00 1.00 1.00 1.00 1.00 1.00 1.00 1.00 1.00 1.00 1.00 1.00 1.00 1.00 1.00 1.00 1.00 1.00 1.00 1.00 1.00 1.00 1.00 1.00 1.00 1.00 1.00 1.00 1.00 1.00 1.00 1.00 1.00 1.00 1.00 1.00 1.00 1.00 1.00 1.00 1.00 1.00 1.00 1.00 1.00 1.00 1.00 1.00 1.00 1.00 1.00 1.00 1.00 1.00 1.00 1.00 1.00 1.00 1.00 1.00 1.00 1.00 1.00 1.00 1.00 1.00 1.00 1.00 1.00 1.00 1.00 1.00 1.00 1.00 1.00 1.00 1.00 1.00 1.00 1.00 1.00 1.00 1.00 1.00 1.00 1.00 1.00 1.00 1.00 1.00 1.00 1.00 1.00 1.00 1.00 1.00 1.00 1.00 1.00 1.00 1.00 1.00 1.00 1.00 1.00 1.00 1.00 1.00 1.00 1.00 1.00 1.00 1.00 1.00 1.00 1.00 1.00 1.00 1.00 1.00 1.00 1.00 1.00 1.00 1.00 1.00 1.00 1.00 1.00 1.00 1.00 1.00 1.00 1.00 1.00 1.00 1.00 1.00 1.00 1.00 1.00 1.00 1.00 1.00 1.00 1.00 1.00 1.00 1.00 1.00 1.00 1.00 1.00 1.00 1.00 1.00 1.00 1.00 1.00 1.00 1.00 1.00 1.00 1.00 1.00 1.00 1.00 1.00 1.00 1.00 1.00 1.00 1.00 1.00 1.00 1.00 1.00 1.00 1.00 1.00 1.00 1.00 1.00 1.00 1.00 1.00 1.00 1.00 1.00 1.00 1.00 1.00 1.00 1.00 1.00 1.00 1.00 1.00 1.00 1.00 1.00 1.00 1.00 1.00 1.00 1.00 1.00 1.00 1.00 1.00 1.00 1.00 1.00 1.00 1.00 1.00 1.00 1.00 1.00 1.00 1.00 1.00 1.00 1.00 1.00 1.00 1.00 1.00 1.00 1.00 1.00 1.00 1.00 1.00 1.00 1.00 1.00 1.00 1.00 1.00 1.00 1.00 1.00 1.00 1.00 1.00 1.00 1.00 1.00 1.00 1.00 1.00 1.00 1.00 1.00 1.00 1.00 1.00 1.00 1.00 1.00 1.00 1.00 1.00 1.00 1.00 1.00 1.00 1.00 1.00 1.00 1.00 1.00 1.00 1.00 1.00 1.00 1.00 1.00 1.00 1.00 1.00 1.00 1.00 1.00 1.00 1.00 1.00 1.00 1.00 1.00 1.00 1.00 1.00 1.00 1.00 1.00 1.00 1.00 1.00 1.00 1.00 1.00 1.00 1.00 1.00 1.00 1.00 1.00 1.00 1.00 1.00 1.00 1.00 1.00 1.00 1.00 1.00 1.00 1.00 1.00 1.00 1.00 1.00 1.00 1.00 1.00 1.00 1.00 1.00 1.00 1.00 1.00 1.00 1.00 1.00 1.00 1.00 1.00 1.00 1.00 1.00 1.00 1.00 1.00 1.00 1.00 1.00 1.00 1.00 1.00 1.00 1.00 1.00 1.00 1.00 1.00 1.00 1.00 1.00 1.00 1.00 1.00 1.00 1.00 1.00 1.00 1.00 1.00 1.00 1.00 1.00 1.00 1.00 1.00 1.00 1.00 1.00 1.00 1.00 1.00 1.00 1.00 1.00 1.00 1.00 1.00 1.00 1.00 1.00 1.00 1.00 1.00 1.00 1.00 1.00 1.00 1.00 1.00 1.00 1.00 1.00 1.00 1.00 1.00 1.00 1.00 1.00 1.00 1.00 1.00 1.00 1.00 1.00 1.00 1.00 1.00 1.00 1.00 1.00 1.00 1.00 1.00 1.00 1.00 1.00 1.00 1.00 1.00 1.00 1.00 1.00 1.00 1.00 1.00 1.00 1.00 1.00 1.00 1.00 1.00 1.00 1.00 1.00 1.00 1.00 1.00 1.00 1.00 1.00 1.00 1.00 1.00 1.00 1.00 1.00 1.00 1.00 1.00 1.00 1.00 1.00 1.00 1.00 1.00 1.00 1.00 1.00 1.00 1.00 1.00 1.00 1.00 1.00 1.00 1.00 1.00 1.00 1.00 1.00 1.00 1.00 1.00 1.00 1.00 1.00 1.00 1.00 1.00 1.00 1.00 1.00 1.00 1.00 1.00 1.00 1.00 1.00 1.00 1.00 1.00 1.00 1.00 1.00 1.00 1.00 1.00 1.00 1.00 1.00 1.00 1.00 1.00 1.00 1.00 1.00 1.00 1.00 1.00 1.00 1.00 1.00 1.00 1.00 1.00 1.00 1.00 1.00 1.00 1.00 1.00 1.00 1.00 1.00 1.00 1.00 1.00 1.00 1.00 1.00 1.00 1.00 1.00 1.00 1.00 1.00 1.00 1.00 1.00 1.00 1.00 1.00 1.00 1.00 1.00 1.00 1.00 1.00 1.00 1.00 1.00 1.00 1.00 1.00 1.00 1.00 1.00 1.00 1.00 1.00 1.00 1.00 1.00 1.00 1.00 1.00 1.00 1.00 1.00 1.00 1.00 1.00 1.00 1.00 1.00 1.00 1.00 1.00 1.00 1.00 1.00 1.00 1.00 1.00 1.00 1.00 1.00 1.00 1.00 1.00 1.00 1.00 1.00 1.00 1.00 1.00 1.00 1.00 1.00 1.00 1.00 1.00 1.00 1.00 1.00 1.00 1.00 1.00 1.00 1.00 1.00 1.00 1.00 1.00 1.00 1.00 1.00 1.00 1.00 1.00 1.00 1.00 1.00 1.00 1.00 1.00 1.00 1.00 1.00 1.00 1.00 1.00 1.00 1.00 1.00 1.00 1.00 1.00 1.00 1.00 1.00 1.00 1.00 1.00 1.00 1.00 1.00 1.00 1.00 1.00 1.00 1.00 1.00 1.00 1.00 1.00 1.00 1.00 1.00 1.00 1.00 1.00 1.00 1.00 1.00 1.00 1.00 1.00 1.00 1.00 1.00 1.00 1.00 1.00 1.00 1.00 1.00 1.00 1.00 1.00 1.00 1.00 1.00 1.00 1.00 1.00 1.00 1.00 1.00 1.00 1.00 1.00 1.00 1.00 1.00 1.00 1.00 1.00 1.00 1.00 1.00 1.00 1.00 1.00 1.00 1.00 1.00 1.00 1.00 1.00 1.00 1.00 1.00 1.00 1.00 1.00 1.00 1.00 1.00 1.00 1.00 1.00 1.00 1.00 1.00 1.00 1.00 1.00 1.00 1.00 1.00 1.00 1.00 1.00 1.00 1.00 1.00 1.00 1.00 1.00 1.00 1.00 1.00 1.00 1.00 1.00 1.00 1.00 1.00 1.00 1.00 1.00 1.00 1.00 1.00 1.00 1.00 1.00 1.00 1.00 1.00 1.00 1.00 1.00 1.00 1.00 1.00 1.00 1.00 1.00 1.00 1.00 1.00 1.00 1.00 1.00 1.00 1.00 1.00 1.00 1.00 1.00 1.00 1.00 1.00 1.00 1.00 1.00 1.00 1.00 1.00 1.00 1.00 1.00 1.00 1.00 1.00 1.00 1.00 1.00 1.00 1.00 1.00 1.00 1.00 1.00 1.00 1.00 1.00 1.00 1.00 1.00 1.00 1.00 1.00 1.00 1.00 1.00 1.00 1.00 1.00 1.00 1.00 1.00 1.00 1.00 1.00 1.00 1.00 1.00 1.00 1.00 1.00 1.00 1.00 1.00 1.00 1.00 1.00 1.00 1.00 1.00 1.00 1.00 1.00 1.00 1.00 1.00 1.00 1.00 1.00 1.00 1.00 1.00 1.00 1.00 1.00 1.00 1.00 1.00 1.00 1.00 1.00 1.00 1.00 1.00 1.00 1.00 1.00 1.00 1.00 1.00 1.00 1.00 1.00 1.00 1.00 1.00 1.00 1.00 1.00 1.00 1.00 1.00 1.00 1.00 1.00 1.00 1.00 1.00 1.00 1.00 1.00 1.00 1.00 1.00 1.00 1.00 1.00 1.00 1.00 1.00 1.00 1.00 1.00 1.00 1.00 1.00 1.00 1.00 1.00 1.00 1.00 1.00 1.00 1.00 1.00 1.00 1.00 1.00 1.00 1.00 1.00 1.00 1.00 1.00 1.00 1.00 1.00 1.00 1.00 1.00 1.00 1.00 1.00 1.00 1.00 1.00 1.00 1.00 1.00 1.00 1.00 1.00 1.00 1.00 1.00 1.00 1.00 1.00 1.00 1.00 1.00 1.00 1.00 1.00 1.00 1.00 1.00 1.00 1.00 1.00 1.00 1.00 1.00 1.00 1.00 1.00 1.00 1.00 1.00 1.00 1.00 1.00 1.00 1.00 1.00 1.00 1.00 1.00 1.00 1.00 1.00 1.00 1.00 1.00 1.00 1.00 1.00 1.00 1.00 1.00 1.00 1.00 1.00 1.00 1.00 1.00 1.00 1.00 1.00 1.00 1.00 1.00 1.00 1.00 1.00 1.00 1.00 1.00 1.00 1.00 1.00 1.00 1.00 1.00 1.00 1.00 1.00 1.00 1.00 1.00 1.00 1.00 1.00 1.00 1.00 1.00 1.00 1.00 1.00 1.00 1.00 1.00 1.00 1.00 1.00 1.00 1.00 1.00 1.00 1.00 1.00 1.00 1.00 1.00 1.00 1.00 1.00 1.00 1.00 1.00 1.00 1.00 1.00 1.00 1.00 1.00 1.00 1.00 1.00 1.00 1.00 1.00 1.00 1.00 1.00 1.00 1.00 1.00 1.00 1.00 1.00 1.00 1.00 1.00 1.00 1.00 1.00 1.00 1.00 1.00 1.00 1.00 1.00 1.00 1.00 1.00 1.00 1.00 1.00 1.00 1.00 1.00 1.00 1.00 1.00 1.00 1.00 1.00 1.00 1.00 1.00 1.00 1.00 1.00 1.00 1.00 1.00 1.00 1.00 1.00 1.00 1.00 1.00 1.00 1.00 1.00 1.00 1.00 1.00 1.00 1.00 1.00 1.00 1.00 1.00 1.00 1.00 1.00 1.00 1.00 1.00 1.00 1.00 1.00 1.00 1.00 1.00 1.00 1.00 1.00 1.00 1.00 1.00 1.00 1.00 1.00 1.00 1.00 1.00 1.00 1.00 1.00 1.00 1.00 1.00 1.00 1.00 1.00 1.00 1.00 1.00 1.00 1.00 1.00 1.00 1.00 1.00 1.00 1.00 1.00 1.00 1.00 1.00 1.00 1.00 1.00 1.00 1.00 1.00 1.00 1.00 1.00 1.00 1.00 1.00 1.00 1.00 1.00 1.00 1.00 1.00 1.00 1.00 1.00 1.00 1.00 1.00 1.00 1.00 1.00 1.00 1.00 1.00 1.00 1.00 1.00 1.00 1.00 1.00 1.00 1.00 1.00 1.00 1.00 1.00 1.00 1.00 1.00 1.00 1.00 1.00 1.00 1.00 1.00 1.00 1.00 1.00 1.00 1.00 1.00 1.00 1.00 1.00 1.00 1.00 1.00 1.00 1.00 1.00 1.00 1.00 1.00 1.00 1.00 1.00 1.00 1.00 1.00 1.00 1.00 1.00 1.00 1.00 1.00 1.00 1.00 1.00 1.00 1.00 1.00 1.00 1.00 1.00 1.00 1.00 1.00 1.00 1.00 1.00 1.00 1.00 1.00 1.00 1.00 1.00 1.00 1.00 1.00 1.00 1.00 1.00 1.00 1.00 1.00 1.00 1.00 1.00 1.00 1.00 1.00 1.00 1.00 1.00 1.00 1.00 1.00 1.00 1.00 1.00 1.00 1.00 1.00 1.00 1.00 1.00 1.00 1.00 1.00 1.00 1.00 1.00 1.00 1.00 1.00 1.00 1.00 1.00 1.00 1.00 1.00 1.00 1.00 1.00 1.00 1.00 1.00 1.00 1.00 1.00 1.00 1.00 1.00 1.00 1.00 1.00 1.00 1.00 1.00 1.00 1.00 1.00 1.00 1.00 1.00 1.00 1.00 1.00 1.00 1.00 1.00 1.00 1.00 1.00 1.00 1.00 1.00 1.00 1.00 1.00 1.00 1.00 1.00 1.00 1.00 1.00 1.00 1.00 1.00 1.00 1.00 1.00 1.00 1.00 1.00 1.00 1.00 1.00 1.00 1.00 1.00 1.00 1.00 1.00 1.00 1.00 1.00 1.00 1.00 1.00 1.00 1.00 1.00 1.00 1.00 1.00 1.00 1.00 1.00 1.00 1.00 1.00 1.00 1.00 1.00 1.00 1.00 1.00 1.00 1.00 1.00 1.00 1.00 1.00 1.00 1.00 1.00 1.00 1.00 1.00 1.00 1.00 1.00 1.00 1.00 1.00 1.00 1.00 1.00 1.00 1.00 1.00 1.00 1.00 1.00 1.00 1.00 1.00 1.00 1.00 1.00 1.00 1.00 1.00 1.00 1.00 1.00 1.00 1.00 1.00 1.00 1.00 1.00 1.00 1.00 1.00 1.00 1.00 1.00 1.00 1.00 1.00 1.00 1.00 1.00 1.00 1.00 1.00 1.00 1.00 1.00 1.00 1.00 1.00 1.00 1.00 1.00 1.00 1.00 1.00 1.00 1.00 1.00 1.00 1.00 1.00 1.00 1.00 1.00 1.00 1.00 1.00 1.00 1.00 1.00 1.00 1.00 1.00 1.00 1.00 1.00 1.00 1.00 1.00 1.00 1.00 1.00 1.00 1.00 1.00 1.00 1.00 1.00 1.00 1.00 1.00 1.00 1.00 1.00 1.00 1.00 1.00 1.00 1.00 1.00 1.00 1.00 1.00 1.00 1.00 1.00 1.00 1.00 1.00 1.00 1.00 1.00 1.00 1.00 1.00 1.00 1.00 1.00 1.00 1.00 1.00 1.00 1.00 1.00 1.00 1.00 1.00 1.00 1.00 1.00 1.00 1.00 1.00 1.00 1.00 1.00 1.00 1.00 1.00 1.00 1.00 1.00 1.00 1.00 1.00 1.00 1.00 1.00 1.00 1.00 1.00 1.00 1.00 1.00 1.00 1.00 1.00 1.00 1.00 1.00 1.00 1.00 1.00 1.00 1.00 1.00 1.00 1.00 1.00 1.00 1.00 1.00 1.00 1.00 1.00 1.00 1.00 1.00 1.00 1.00 1.00 1.00 1.00 1.00 1.00 1.00 1.00 1.00 1.00 1.00 1.00 1.00 1.00 1.00 1.00 1.00 1.00 1.00 1.00 1.00 1.00 1.00 1.00 1.00 1.00 1.00 1.00 1.00 1.00 1.00 1.00 1.00 1.00 1.00 1.00 1.00 1.00 1.00 1.00 1.00 1.00 1.00 1.00 1.00 1.00 1.00 1.00 1.00 1.00 1.00 1.00 1.00 1.00 1.00 1.00 1.00 1.00 1.00 1.00 1.00 1.00 1.00 1.00 1.00 1.00 1.00 1.00 1.00 1.00 1.00 1.00 1.00 1.00 1.00 1.00 1.00 1.00 1.00 1.00 1.00 1.00 1.00 1.00 1.00 1.00 1.00 1.00 1.00 1.00 1.00 1.00 1.00 1.00 1.00 1.00 1.00 1.00 1.00 1.00 1.00 1.00 1.00 1.00 1.00 1.00 1.00 1.00 1.00 1.00 1.00 1.00 1.00 1.00 1.00 1.00 1.00 1.00 1.00 1.00 1.00 1.00 1.00 1.00 1.00 1.00 1.00 1.00 1.00 1.00 1.00 1.00 1.00 1.00 1.00 1.00 1.00 1.00 1.00 1.00</beamAttenuationFactors>
				<commonCountingTime unit="seconds">0.60</commonCountingTime>
				<intensities unit="counts">4 7 10 4 5 7 8 7 5 6 4 3 11 5 7 8 9 5 9 3 7 8 12 6 11 12 8 10 14 8 17 12 19 15 16 8 13 15 11 6 10 8 9 2 7 9 10 11 6 8 9 7 8 6 5 13 11 8 6 6 6 8 9 4 5 8 7 7 2 8 4 8 9 13 7 5 4 7 8 8 9 8 9 10 9 7 6 7 8 4 5 6 10 11 7 10 6 10 8 4 6 6 9 7 7 12 6 8 9 12 7 6 10 7 8 8 10 8 11 9 12 9 9 10 5 8 11 6 7 13 9 6 6 9 16 7 7 6 7 11 4 7 10 11 7 12 5 10 6 8 14 6 10 11 9 7 14 16 7 6 9 8 12 8 9 8 11 11 9 9 13 9 14 6 5 11 14 14 7 8 14 13 6 11 13 7 12 14 16 12 15 10 13 10 9 6 10 9 8 9 16 7 11 9 15 11 11 13 9 12 11 23 13 13 16 12 5 11 14 12 9 15 10 10 10 7 7 12 8 19 13 18 8 16 5 14 16 14 10 11 19 14 16 22 7 12 19 14 11 16 13 17 19 19 18 16 16 19 20 15 18 17 17 13 14 15 12 19 25 18 21 24 24 24 21 16 22 22 18 18 18 22 18 21 21 19 24 23 21 22 25 30 22 23 26 29 32 26 32 25 23 24 31 26 35 29 24 25 28 24 26 24 37 38 38 22 41 42 32 29 33 41 41 37 36 30 47 41 40 45 39 45 44 52 39 59 39 58 44 48 54 56 49 62 64 54 75 67 67 72 76 64 83 83 90 109 100 98 84 110 120 105 126 124 169 147 131 202 198 212 224 282 317 351 435 512 661 987 1499 2604 10715 129804 325449 84793 374527 320092 139664 64984 38621 25713 22177 21935 20749 17498 13942 11390 10515 9359 7797 5368 3435 2622 2652 2640 2125 1143 702 478 388 359 299 234 228 200 204 195 170 148 133 146 126 104 136 114 111 95 95 98 103 92 74 60 91 73 70 67 51 79 62 60 70 59 81 55 55 48 55 44 56 38 55 50 55 38 47 51 37 37 53 57 49 53 45 52 50 42 40 50 49 41 40 50 60 36 60 55 47 41 60 53 46 47 49 43 54 52 45 51 55 63 63 64 61 64 53 62 73 63 60 58 64 60 66 69 74 79 57 73 59 68 66 72 69 75 97 94 91 98 91 99 96 108 110 116 90 109 112 114 153 149 108 122 134 155 158 180 180 166 187 184 194 204 244 251 242 294 328 330 348 371 371 402 439 538 540 616 697 862 931 1089 1231 1530 1775 2062 2624 3242 4007 4983 6030 7320 8926 10536 12250 14323 16189 18406 20338 22429 24197 25601 26674 27655 28164 28703 28458 27609 26726 25566 23667 22142 20261 18314 15948 13922 12311 10479 8764 7351 6144 4984 4175 3330 2717 2155 1838 1443 1236 1060 792 747 630 531 505 472 386 368 330 314 260 248 220 230 216 175 169 144 150 169 162 115 135 114 118 104 110 81 72 91 89 95 63 75 76 73 63 65 58 65 62 39 57 44 55 50 45 46 46 49 42 31 47 37 40 23 36 36 25 28 40 40 31 38 31 31 35 25 22 24 23 25 25 20 27 25 18 28 31 17 24 13 23 22 21 14 26 11 17 19 14 14 22 14 22 9 8 15 8 9 11 15 21 8 15 14 12 11 11 11 17 13 7 10 10 9 12 19 13 9 18 10 14 10 10 7 12 11 10 11 7 12 15 12 5 13 3 13 9 12 5 11 13 8 7 8 4 8 8 3 9 8 5 12 8 8 10 12 8 3 6 7 4 5 7 5 5 8 4 7 7 6 10 3 6 7 8 6 4 4 4 5 10 9 5 3 4 6 6 7 4 5 7 1 6 10 6 7 7 7 1 7 3 7 5 2 4 3 5 8 8 5 3 4 3 4 8 3 9 5 3 3 7 7 2 10 5 5 2 7 5 4 0 7 4 4 6 10 10 8 7 9 6 4 7 3 7 3 3 4 1 2 6 2 6 7 3 7 7 4 6 3 3 7 2 4 4 4 6 2 6 11 2 7 5 3 5 5 7 3 5 5 2 5 4 4 2 9 4 3 5 4 6 4 9 3 5 6 6 4 2 3 6 5 7 2 6 11 9 6 7 1 4 4 2 3 6 4 10 6 4 8 5 4 2 7 1 2 4 5 3 7 0 6 4 5 4 5 2 8 7 3 1 7 0 11 4 3 3 4 2 4 6 6 4 3 0 4 5 6 2 5 3 7 2 4 2 5 3 6 1 6 2 2 4 2 5 5 5 5 6 2 4 7 2 3 4 3 3 5 5 3 3 4 4 5 5 5 4 2 4 5 2 4 7 7 4 3 4 7 3 2 2 4 4 1 2 6 5 5 3 5 4 5 6 4 4 3 4 1 8 3 2 2 7 2 2 1 1 5 2 3 4 6 4 7 1 10 4 3 5 4 6 6 0 7 5 7 2 1 2 4 3 5 5 5 5 6 4 5 4 5 6 3 7 0 7 4 2 4 3 1 5 4 6 8 1 1 3 3 6 2 3 5 2 2 1 3 6 0 6 7 8 2 6 4 3 3 5 3 5 4 5 4 1 4 6 4 3 5 3 3 3 1 6 4 3 5 2 3 4 4 4 2 1 5 7 3 5 3 4 5 2 2 6 0 7 3 1 1 2 1 4 4 2 4 3 3 7 4 1 5 6 6 0 1 7 5 5 1 3 3 3 3 3 2 3 2 1 4 4 3 6 3 3 1 5 2 0 1 2 1 4 6 2 2 1 2 4 4 1 4 2 4 2 6 3 5 5 3 5 4 2 6 3 6 3 6 3 3 5 5 3 4 7 5 2 4 2 0 7 5 8 2 3 1 3 4 5 1 2 3 3 4 2 6 3 0 3 3 3 2 1 4 4 2 2 3 4 6 3 2 3 1 0 4 5 4 4 1 2 3 7 3 5 8 2 3 4 1 6 5 3 1 2 4 4 4 3 5 3 2 1 3 2 2 4 2 3 3 2 5 3 5 2 6 1 3 3 3 2 3 4 6 2 4 0 1 0 4 8 3 4 6 4 2 4 4 4 5 5 3 4 4 4 4 4 3 0 5 3 1 3 5 5 2 3 5 1 3 1 5 2 2 4 3 5 3 4 4 3 3 5 3 1 2 3 1 7 2 7 3 4 3 1 3 3 2 3 3 5 4 4 6 3 4 5 4 3 6 1 4 3 5 2 5 4 5 2 0 3 0 4 5 1 3 2 4 3 4 1 2 2 4 4 3 6 3 7 6 1 7 3 4 3 5 5 1 4 4 6 5 6 5 1 2 1 0 0 3 1 4 4 0 1 3 4 4 2 2 2 2 1 3 3 2 7 2 3 1 3 3 2 2 3 3 3 3 6 4 5 1 2 1 0 4 7 2 1 3 2 4 2 0 2 2 2 2 0 3 2 3 3 0 3 4 2 4 4 1 4 3 3 5 1 1 5 0 4 2 0 4 3 2 6 4 0 4 1 8 0 3 3 3 1 5 6 4 6 5 5 6 6 5 3 3 2 1 1 1 3 3 1 3 3 5 2 1 3 3 1 2 4 3 5 2 3 2 6 3 6 1 6 5 5 4 4 1 2 6 5 5 7 4 5 2 3 3 3 3 2 3 3 6 7 7 3 2 1 5 1 2 2 4 3 3 5 3 4 1 6 1 9 0 3 6 5 3 5 3 2 6 0 0 3 5 2 1 2 5 5 2 10 5 1 3 5 3 4 8 3 2 4 2 4 4 3 2 3 0 2 4 9 4 3 3 3 2 4 4 1 2 3 5 3 4 7 4 3 2 3 6 2 0 1 3 1 3 0 3 4 1 2 2 2 6 3 2 2 5 3 4 1 3 6 4 2 3 3 4 3 1 2 2 3 3 1 5 2 3 4 2 5 1 2 2 4 5 4 2 3 4 2 4 3 6 5 6 2 1 2 2 1 3 4 1 5 1 3 5 4 1 2 0 0 4 3 8 5 3 3 3 2 4 5 7 1 3 1 4 4 2 3 7 6 6 5 3 0 4 1 2 0 4 4 0 6 5 5 1 2 2 2 2 1 1 1 7 4 4 4 3 1 2 3 5 1 2 3 4 1 3 2 6 3 0 4 2 1 2 4 5 7 5 2 4 2 3 4 4 3 4 4 0 1 2 5 3 1 1 4 4 2 4 4 3 6 3 6 2 3 3 3 2 6 3 3 2 4 3 1 4 0 3 3 2 1 4 1 1 4 1 3 3 1 5 5 1 1 3 5 3 1 2 3 2 7 7 2 3 4 4 2 4 7 1 4 5 2 3 4 6 3 8 0 3 0 4 3 2 1 5 1 3 1 6 4 2 2 0 4 3 3 4 2 4 5 3 2 7 2 1 4 2 2 2 1 1 4 3 4 3 3 5 1 3 6 2 3 4 3 1 2 7 3 3 1 4 7 3 2 1 2 1 2 5 3 4 4 2 3 3 0 2 7 4 8 4 2 3 1 0 1 4 4 2 4 3 6 1 3 1 2 3 3 3 3 2 1 3 0 2 1 1 0 0 2 1 4 3 0</intensities>
			</dataPoints>
		</scan>
	</xrdMeasurement>
</xrdMeasurements>