File: KEN002.xrdml
<?xml version="1.0" encoding="UTF-8"?>
<xrdMeasurements xmlns="http://www.xrdml.com/XRDMeasurement/1.5" xmlns:xsi="http://www.w3.org/2001/XMLSchema-instance" xsi:schemaLocation="http://www.xrdml.com/XRDMeasurement/1.5 http://www.xrdml.com/XRDMeasurement/1.5/XRDMeasurement.xsd" status="Completed">
	<comment>
		<entry>Configuration=MRD 2016, Owner=hydrogen, Creation date=09-Dec-16 19:44:12</entry>
		<entry>Goniometer=PW3050/65 (Theta/2Theta); Minimum step size 2Theta:0.001; Minimum step size Omega:0.001</entry>
		<entry>Sample stage=MRD Cradle; Minimum step size Phi:0.01; Minimum step size Chi:0.01; Minimum step size X:0.01; Minimum step size Y:0.01; Minimum step size Z:0.001</entry>
		<entry>Diffractometer system=XPERT-PRO</entry>
		<entry>Measurement program=Manual, Owner=hydrogen, Creation date=31-Jan-19 12:02:40</entry>
		<entry>Fine Calibration Offset for 2Theta = 0.008 deg</entry>
		<entry>Fine Calibration Offset for Omega = -0.180 deg</entry>
	</comment>
	<sample type="To be analyzed">
		<id></id>
		<name></name>
		<preparedBy></preparedBy>
	</sample>
	<xrdMeasurement measurementType="Scan" status="Completed" sampleMode="Reflection">
		<comment>
			<entry>PHD Lower Level = 5.63 (keV), PHD Upper Level = 12.88 (keV)</entry>
		</comment>
		<usedWavelength intended="K-Alpha 1">
			<kAlpha1 unit="Angstrom">1.5405940</kAlpha1>
			<kAlpha2 unit="Angstrom">1.5444080</kAlpha2>
			<kBeta unit="Angstrom">1.3922500</kBeta>
			<ratioKAlpha2KAlpha1>0.5200</ratioKAlpha2KAlpha1>
		</usedWavelength>
		<incidentBeamPath>
			<radius unit="mm">320.00</radius>
			<xRayTube id="1010048" name="Empyrean Cu LFF HR (9430 033 7310x) DK164548">
				<tension unit="kV">45</tension>
				<current unit="mA">40</current>
				<anodeMaterial>Cu</anodeMaterial>
				<focus type="Line">
					<length unit="mm">12.0</length>
					<width unit="mm">0.4</width>
					<takeOffAngle unit="deg">3.5</takeOffAngle>
				</focus>
			</xRayTube>
			<xRayMirror id="27090001" name="Inc. Beam Cu W/Si (hybrid MRD)" hybrid="true">
				<crystal type="Graded" shape="Parabolic">W/Si</crystal>
				<acceptanceAngle unit="deg">0.800</acceptanceAngle>
				<length unit="mm">60.0</length>
			</xRayMirror>
			<monochromator id="23090002" name="Hybrid monochr. 2xGe(220) for Cu" hybrid="true">
				<crystal type="Asymmetric" shape="Flat">Ge</crystal>
				<numberOfReflections>2</numberOfReflections>
				<hkl>
					<h>2</h>
					<k>2</k>
					<l>0</l>
				</hkl>
			</monochromator>
			<divergenceSlit id="22010007" name="Fixed slit 1/8°" xsi:type="fixedDivergenceSlitType">
				<distanceToSample unit="mm">220.00</distanceToSample>
				<height unit="mm">0.19</height>
			</divergenceSlit>
			<beamAttenuator id="26010002" name="Beam attenuator Cu 0.1 mm" xsi:type="intensitySwitchedBeamAttenuatorType">
				<factor>119.20</factor>
				<material>Cu</material>
				<activateLevel unit="counts per second">800000</activateLevel>
				<deactivateLevel unit="counts per second">300000</deactivateLevel>
			</beamAttenuator>
		</incidentBeamPath>
		<sampleOffset>
			<position axis="2Theta" unit="deg">0.000</position>
			<position axis="Omega" unit="deg">-0.085</position>
		</sampleOffset>
		<diffractedBeamPath>
			<radius unit="mm">320.00</radius>
			<parallelPlateCollimator id="25010001" name="Parallel plate collimator 0.27°">
				<opening unit="deg">0.27</opening>
			</parallelPlateCollimator>
			<receivingSlit id="22070001" name="Parallel plate collimator slit">
				<height unit="mm">0.10</height>
			</receivingSlit>
			<detector id="7010011" name="Proportional detector Xe" xsi:type="pointDetectorType">
				<phd>
					<lowerLevel unit="%">35.0</lowerLevel>
					<upperLevel unit="%">80.0</upperLevel>
				</phd>
			</detector>
		</diffractedBeamPath>
		<scan appendNumber="0" mode="Continuous" scanAxis="2Theta-Omega" status="Completed">
			<header>
				<startTimeStamp>2019-01-31T15:41:39+00:00</startTimeStamp>
				<endTimeStamp>2019-01-31T16:07:10+00:00</endTimeStamp>
				<author>
					<name>X-ray User</name>
				</author>
				<source>
					<applicationSoftware version="5.2a">Data Collector</applicationSoftware>
					<instrumentControlSoftware version="2.2B 20140619">XPERT-PRO</instrumentControlSoftware>
					<instrumentID>0000000011014754</instrumentID>
				</source>
			</header>
			<scanAxisCenter>
				<position axis="2Theta" unit="deg">50.000</position>
				<position axis="Omega" unit="deg">25.000</position>
			</scanAxisCenter>
			<reflection>
				<hkl>
					<h>0</h>
					<k>0</k>
					<l>0</l>
				</hkl>
			</reflection>
			<dataPoints>
				<positions axis="2Theta" unit="deg">
					<startPosition>25.020</startPosition>
					<endPosition>74.980</endPosition>
				</positions>
				<positions axis="Omega" unit="deg">
					<startPosition>12.5100</startPosition>
					<endPosition>37.4900</endPosition>
				</positions>
				<positions axis="Phi" unit="deg">
					<commonPosition>0.00</commonPosition>
				</positions>
				<positions axis="Chi" unit="deg">
					<commonPosition>0.00</commonPosition>
				</positions>
				<positions axis="X" unit="mm">
					<commonPosition>0.00</commonPosition>
				</positions>
				<positions axis="Y" unit="mm">
					<commonPosition>0.00</commonPosition>
				</positions>
				<positions axis="Z" unit="mm">
					<commonPosition>6.794</commonPosition>
				</positions>
				<beamAttenuationFactors>1.00 1.00 1.00 1.00 1.00 1.00 1.00 1.00 1.00 1.00 1.00 1.00 1.00 1.00 1.00 1.00 1.00 1.00 1.00 1.00 1.00 1.00 1.00 1.00 1.00 1.00 1.00 1.00 1.00 1.00 1.00 1.00 1.00 1.00 1.00 1.00 1.00 1.00 1.00 1.00 1.00 1.00 1.00 1.00 1.00 1.00 1.00 1.00 1.00 1.00 1.00 1.00 1.00 1.00 1.00 1.00 1.00 1.00 1.00 1.00 1.00 1.00 1.00 1.00 1.00 1.00 1.00 1.00 1.00 1.00 1.00 1.00 1.00 1.00 1.00 1.00 1.00 1.00 1.00 1.00 1.00 1.00 1.00 1.00 1.00 1.00 1.00 1.00 1.00 1.00 1.00 1.00 1.00 1.00 1.00 1.00 1.00 1.00 1.00 1.00 1.00 1.00 1.00 1.00 1.00 1.00 1.00 1.00 1.00 1.00 1.00 1.00 1.00 1.00 1.00 1.00 1.00 1.00 1.00 1.00 1.00 1.00 1.00 1.00 1.00 1.00 1.00 1.00 1.00 1.00 1.00 1.00 1.00 1.00 1.00 1.00 1.00 1.00 1.00 1.00 1.00 1.00 1.00 1.00 1.00 1.00 1.00 1.00 1.00 1.00 1.00 1.00 1.00 1.00 1.00 1.00 1.00 1.00 1.00 1.00 1.00 1.00 1.00 1.00 1.00 1.00 1.00 1.00 1.00 1.00 1.00 1.00 1.00 1.00 1.00 1.00 1.00 1.00 1.00 1.00 1.00 1.00 1.00 1.00 1.00 1.00 1.00 1.00 1.00 1.00 1.00 1.00 1.00 1.00 1.00 1.00 1.00 1.00 1.00 1.00 1.00 1.00 1.00 1.00 1.00 1.00 1.00 1.00 1.00 1.00 1.00 1.00 1.00 1.00 1.00 1.00 1.00 1.00 1.00 1.00 1.00 1.00 1.00 1.00 1.00 1.00 1.00 1.00 1.00 1.00 1.00 1.00 1.00 1.00 1.00 1.00 1.00 1.00 1.00 1.00 1.00 1.00 1.00 1.00 1.00 1.00 1.00 1.00 1.00 1.00 1.00 1.00 1.00 1.00 1.00 1.00 1.00 1.00 1.00 1.00 1.00 1.00 1.00 1.00 1.00 1.00 1.00 1.00 1.00 1.00 1.00 1.00 1.00 1.00 1.00 1.00 1.00 1.00 1.00 1.00 1.00 1.00 1.00 1.00 1.00 1.00 1.00 1.00 1.00 1.00 1.00 1.00 1.00 1.00 1.00 1.00 1.00 1.00 1.00 1.00 1.00 1.00 1.00 1.00 1.00 1.00 1.00 1.00 1.00 1.00 1.00 1.00 1.00 1.00 1.00 1.00 1.00 1.00 1.00 1.00 1.00 1.00 1.00 1.00 1.00 1.00 1.00 1.00 1.00 1.00 1.00 1.00 1.00 1.00 1.00 1.00 1.00 1.00 1.00 1.00 1.00 1.00 1.00 1.00 1.00 1.00 1.00 1.00 1.00 1.00 1.00 1.00 1.00 1.00 1.00 1.00 1.00 1.00 1.00 1.00 1.00 1.00 1.00 1.00 1.00 1.00 1.00 1.00 1.00 1.00 1.00 1.00 1.00 1.00 1.00 1.00 1.00 1.00 1.00 1.00 1.00 1.00 1.00 1.00 1.00 1.00 1.00 1.00 1.00 1.00 1.00 1.00 1.00 1.00 1.00 1.00 1.00 1.00 1.00 1.00 1.00 1.00 1.00 1.00 1.00 1.00 1.00 1.00 1.00 1.00 1.00 1.00 1.00 1.00 1.00 1.00 1.00 1.00 1.00 1.00 1.00 1.00 1.00 1.00 1.00 1.00 1.00 1.00 1.00 1.00 1.00 1.00 1.00 1.00 1.00 1.00 1.00 1.00 1.00 1.00 1.00 1.00 1.00 1.00 1.00 1.00 1.00 1.00 1.00 1.00 1.00 1.00 1.00 1.00 1.00 1.00 1.00 1.00 1.00 1.00 1.00 1.00 1.00 1.00 1.00 1.00 1.00 1.00 1.00 1.00 1.00 1.00 1.00 1.00 1.00 1.00 1.00 1.00 1.00 1.00 1.00 1.00 1.00 1.00 1.00 1.00 1.00 1.00 1.00 1.00 1.00 1.00 1.00 1.00 1.00 1.00 1.00 1.00 1.00 1.00 1.00 1.00 1.00 1.00 1.00 1.00 1.00 1.00 1.00 1.00 1.00 1.00 1.00 1.00 1.00 1.00 1.00 1.00 1.00 1.00 1.00 1.00 1.00 1.00 1.00 1.00 1.00 1.00 1.00 1.00 1.00 1.00 1.00 1.00 1.00 1.00 1.00 1.00 1.00 1.00 1.00 1.00 1.00 1.00 1.00 1.00 1.00 1.00 1.00 1.00 1.00 1.00 1.00 1.00 1.00 1.00 1.00 1.00 1.00 1.00 1.00 1.00 1.00 1.00 1.00 1.00 1.00 1.00 1.00 1.00 1.00 1.00 1.00 1.00 1.00 1.00 1.00 1.00 1.00 1.00 1.00 1.00 1.00 1.00 1.00 1.00 1.00 1.00 1.00 1.00 1.00 1.00 1.00 1.00 1.00 1.00 1.00 1.00 1.00 1.00 1.00 1.00 1.00 1.00 1.00 1.00 1.00 1.00 1.00 1.00 1.00 1.00 1.00 1.00 1.00 1.00 1.00 1.00 1.00 1.00 1.00 1.00 1.00 1.00 1.00 1.00 1.00 1.00 1.00 1.00 1.00 1.00 1.00 1.00 1.00 1.00 1.00 1.00 1.00 1.00 1.00 1.00 1.00 1.00 1.00 1.00 1.00 1.00 1.00 1.00 1.00 1.00 1.00 1.00 1.00 1.00 1.00 1.00 1.00 1.00 1.00 1.00 1.00 1.00 1.00 1.00 1.00 1.00 1.00 1.00 1.00 1.00 1.00 1.00 1.00 1.00 1.00 1.00 1.00 1.00 1.00 1.00 1.00 1.00 1.00 1.00 1.00 1.00 1.00 1.00 1.00 1.00 1.00 1.00 1.00 1.00 1.00 1.00 1.00 1.00 1.00 1.00 1.00 1.00 1.00 1.00 1.00 1.00 1.00 1.00 1.00 1.00 1.00 1.00 1.00 1.00 1.00 1.00 1.00 1.00 1.00 1.00 1.00 1.00 1.00 1.00 1.00 1.00 1.00 1.00 1.00 1.00 1.00 1.00 1.00 1.00 1.00 1.00 1.00 1.00 1.00 1.00 1.00 1.00 1.00 1.00 1.00 1.00 1.00 1.00 1.00 1.00 1.00 1.00 1.00 1.00 1.00 1.00 1.00 1.00 1.00 1.00 1.00 1.00 1.00 1.00 1.00 1.00 1.00 1.00 1.00 1.00 1.00 1.00 1.00 1.00 1.00 1.00 1.00 1.00 1.00 1.00 1.00 1.00 1.00 1.00 1.00 1.00 1.00 1.00 1.00 1.00 1.00 1.00 1.00 1.00 1.00 1.00 1.00 1.00 1.00 1.00 1.00 1.00 1.00 1.00 1.00 1.00 1.00 1.00 1.00 1.00 1.00 1.00 1.00 1.00 1.00 1.00 1.00 1.00 1.00 1.00 1.00 1.00 1.00 1.00 1.00 1.00 1.00 1.00 1.00 1.00 1.00 1.00 1.00 1.00 1.00 1.00 1.00 1.00 1.00 1.00 1.00 1.00 1.00 1.00 1.00 1.00 1.00 1.00 1.00 1.00 1.00 1.00 1.00 1.00 1.00 1.00 1.00 1.00 1.00 1.00 1.00 1.00 1.00 1.00 1.00 1.00 1.00 1.00 1.00 1.00 1.00 1.00 1.00 1.00 1.00 1.00 1.00 1.00 1.00 1.00 1.00 1.00 1.00 1.00 1.00 1.00 1.00 1.00 1.00 1.00 1.00 1.00 1.00 1.00 1.00 1.00 1.00 1.00 1.00 1.00 1.00 1.00 1.00 1.00 1.00 1.00 1.00 1.00 1.00 1.00 1.00 1.00 1.00 1.00 1.00 1.00 1.00 1.00 1.00 1.00 1.00 1.00 1.00 1.00 1.00 1.00 1.00 1.00 1.00 1.00 1.00 1.00 1.00 1.00 1.00 1.00 1.00 1.00 1.00 1.00 1.00 1.00 1.00 1.00 1.00 1.00 1.00 1.00 1.00 1.00 1.00 1.00 1.00 1.00 1.00 1.00 1.00 1.00 1.00 1.00 1.00 1.00 1.00 1.00 1.00 1.00 1.00 1.00 1.00 1.00 1.00 1.00 1.00 1.00 1.00 1.00 1.00 1.00 1.00 1.00 1.00 1.00 1.00 1.00 1.00 1.00 1.00 1.00 1.00 1.00 1.00 1.00 1.00 1.00 1.00 1.00 1.00 1.00 1.00 1.00 1.00 1.00 1.00 1.00 1.00 1.00 1.00 1.00 1.00 1.00 1.00 1.00 1.00 1.00 1.00 1.00 1.00 1.00 1.00 1.00 1.00 1.00 1.00 1.00 1.00 1.00 1.00 1.00 1.00 1.00 1.00 1.00 1.00 1.00 1.00 1.00 1.00 1.00 1.00 1.00 1.00 1.00 1.00 1.00 1.00 1.00 1.00 1.00 1.00 1.00 1.00 1.00 1.00 1.00 1.00 1.00 1.00 1.00 1.00 1.00 1.00 1.00 1.00 1.00 1.00 1.00 1.00 1.00 1.00 1.00 1.00 1.00 1.00 1.00 1.00 1.00 1.00 1.00 1.00 1.00 1.00 1.00 1.00 1.00 1.00 1.00 1.00 1.00 1.00 1.00 1.00 1.00 1.00 1.00 1.00 1.00 1.00 1.00 1.00 1.00 1.00 1.00 1.00 1.00 1.00 1.00 1.00 1.00 1.00 1.00 1.00 1.00 1.00 1.00 1.00 1.00 1.00 1.00 1.00 1.00 1.00 1.00 1.00 1.00 1.00 1.00 1.00 1.00 1.00 1.00 1.00 1.00 1.00 1.00 1.00 1.00 1.00 1.00 1.00 1.00 1.00 1.00 1.00 1.00 1.00 1.00 1.00 1.00 1.00 1.00 1.00 1.00 1.00 1.00 1.00 1.00 1.00 1.00 1.00 1.00 1.00 1.00 1.00 1.00 1.00 1.00 1.00 1.00 1.00 1.00 1.00 1.00 1.00 1.00 1.00 1.00 1.00 1.00 1.00 1.00 1.00 1.00 1.00 1.00 1.00 1.00 1.00 1.00 1.00 1.00 1.00 1.00 1.00 1.00 1.00 1.00 1.00 1.00 1.00 1.00 1.00 1.00 1.00 1.00 1.00 1.00 1.00 1.00 1.00 1.00 1.00 1.00 1.00 1.00 1.00 1.00 1.00 1.00 1.00 1.00 1.00 1.00 1.00 1.00 1.00 1.00 1.00 1.00 1.00 1.00 1.00 1.00 1.00 1.00 1.00 1.00 1.00 1.00 1.00 1.00 1.00 1.00 1.00 1.00 1.00 1.00 1.00 1.00 1.00 1.00 1.00 1.00 1.00 1.00 1.00 1.00 1.00 1.00 1.00 1.00 1.00 1.00 1.00 1.00 1.00 1.00 1.00 1.00 1.00 1.00 1.00 1.00 1.00 1.00 1.00 1.00 1.00 1.00 1.00 1.00 1.00 1.00 1.00 1.00 1.00 1.00 1.00 1.00 1.00 1.00 1.00 1.00 1.00 1.00 1.00 1.00 1.00 1.00 1.00 1.00 1.00 1.00 1.00 1.00 1.00 1.00 1.00 1.00 1.00 1.00 1.00 1.00 1.00 1.00 1.00 1.00 1.00 1.00 1.00 1.00 1.00 1.00 1.00 1.00 1.00 1.00 1.00 1.00 1.00 1.00 1.00 1.00 1.00 1.00 1.00 1.00 1.00 1.00 1.00 1.00 1.00 1.00 1.00 1.00 1.00 1.00 1.00 1.00 1.00 1.00 1.00 1.00 1.00 1.00 1.00 1.00 1.00 1.00 1.00 1.00 1.00 1.00 1.00 1.00 1.00 1.00 1.00 1.00 1.00 1.00 1.00 1.00 1.00 1.00 1.00 1.00 1.00 1.00 1.00 1.00 1.00 1.00 1.00 1.00 1.00 1.00 1.00 1.00 1.00 1.00 1.00 1.00 1.00 1.00 1.00 1.00 1.00 1.00 1.00 1.00 1.00 1.00 1.00 1.00 1.00 1.00 1.00 1.00 1.00 1.00 1.00 1.00 1.00 1.00 1.00 1.00 1.00 1.00 1.00 1.00 1.00 1.00 1.00 1.00 1.00 1.00 1.00 1.00 1.00 1.00 1.00 1.00 1.00 1.00 1.00 1.00 1.00 1.00 1.00 1.00 1.00 1.00 1.00 1.00 1.00 1.00 1.00 1.00 1.00 1.00 1.00 1.00 1.00 1.00 1.00 1.00 1.00 1.00 1.00 1.00 1.00 1.00 1.00 1.00 1.00 1.00 1.00 1.00 1.00 1.00 1.00 1.00 1.00 1.00 1.00 1.00 1.00 1.00 1.00 1.00 1.00 1.00 1.00 1.00 1.00 1.00 1.00 1.00 1.00 1.00 1.00 1.00 1.00 1.00 1.00 1.00 1.00 1.00 1.00 1.00 1.00 1.00 1.00 1.00 1.00 1.00 1.00 1.00 1.00 1.00 1.00 1.00 1.00 1.00 1.00 1.00 1.00 1.00 1.00 1.00 1.00 1.00 1.00 1.00 1.00 1.00 1.00 1.00 1.00 1.00 1.00 1.00 1.00 1.00 1.00 1.00 1.00 1.00 1.00 1.00 1.00 1.00 1.00 1.00 1.00 1.00 1.00 1.00 1.00 1.00 1.00 1.00 1.00 1.00 1.00 1.00 1.00 1.00 1.00 1.00 1.00 1.00 1.00 1.00 1.00 1.00 1.00 1.00 1.00 1.00 1.00 1.00 1.00 1.00 1.00 1.00 1.00 1.00 1.00 1.00 1.00 1.00 1.00 1.00 1.00 1.00 1.00 1.00 1.00 1.00 1.00 1.00 1.00 1.00 1.00 1.00 1.00 1.00 1.00 1.00 1.00 1.00 1.00 1.00 1.00 1.00 1.00 1.00 1.00 1.00 1.00 1.00 1.00 1.00 1.00 1.00 1.00 1.00 1.00 1.00 1.00 1.00 1.00 1.00 1.00 1.00 1.00 1.00 1.00 1.00 1.00 1.00 1.00 1.00 1.00 1.00 1.00 1.00 1.00 1.00 1.00 1.00 1.00 1.00 1.00 1.00 1.00 1.00 1.00 1.00 1.00 1.00 1.00 1.00 1.00 1.00 1.00 1.00 1.00 1.00 1.00 1.00 1.00 1.00 1.00 1.00 1.00 1.00 1.00 1.00 1.00 1.00 1.00 1.00 1.00 1.00 1.00 1.00 1.00 1.00 1.00 1.00 1.00 1.00 1.00 1.00 1.00 1.00 1.00 1.00 1.00 1.00 1.00 1.00 1.00 1.00 1.00 1.00 1.00 1.00 1.00 1.00 1.00 1.00 1.00 1.00 1.00 1.00 1.00 1.00 1.00 1.00 1.00 1.00 1.00 1.00 1.00 1.00 1.00 1.00 1.00 1.00 1.00 1.00 1.00 1.00 1.00 1.00 1.00 1.00 1.00 1.00 1.00 1.00 1.00 1.00 1.00 1.00 1.00 1.00 1.00 1.00 1.00 1.00 1.00 1.00 1.00 1.00 1.00 1.00 1.00 1.00 1.00 1.00 1.00 1.00 1.00 1.00 1.00 1.00 1.00 1.00 1.00 1.00 1.00 1.00 1.00 1.00 1.00 1.00 1.00 1.00 1.00 1.00 1.00 1.00 1.00 1.00 1.00 1.00 1.00 1.00 1.00 1.00 1.00 1.00 1.00 1.00 1.00 1.00 1.00 1.00 1.00 1.00 1.00 1.00 1.00 1.00 1.00 1.00 1.00 1.00 1.00 1.00 1.00 1.00 1.00 1.00 1.00 1.00 1.00 1.00 1.00 1.00 1.00 1.00 1.00 1.00 1.00 1.00 1.00 1.00 1.00 1.00 1.00 1.00 1.00 1.00 1.00 1.00 1.00 1.00 1.00 1.00 1.00 1.00 1.00 1.00 1.00 1.00 1.00 1.00 1.00 1.00 1.00 1.00 1.00 1.00 1.00 1.00 1.00 1.00 1.00 1.00 1.00 1.00 1.00 1.00 1.00 1.00 1.00 1.00 1.00 1.00 1.00 1.00 1.00 1.00 1.00 1.00 1.00 1.00 1.00 1.00 1.00 1.00 1.00 1.00 1.00 1.00 1.00 1.00 1.00 1.00 1.00 1.00 1.00 1.00 1.00 1.00 1.00 1.00 1.00 1.00 1.00 1.00 1.00 1.00 1.00 1.00 1.00 1.00 1.00 1.00 1.00 1.00 1.00 1.00 1.00 1.00 1.00 1.00 1.00 1.00 1.00 1.00 1.00 1.00 1.00 1.00 1.00 1.00 1.00 1.00 1.00 1.00 1.00 1.00 1.00 1.00 1.00 1.00 1.00 1.00 1.00 1.00 1.00 1.00 1.00 1.00 1.00 1.00 1.00 1.00 1.00 1.00 1.00 1.00 1.00 1.00 1.00 1.00 1.00 1.00 1.00 1.00 1.00 1.00 1.00 1.00 1.00 1.00 1.00 1.00 1.00 1.00 1.00 1.00 1.00 1.00 1.00 1.00 1.00 1.00 1.00 1.00 1.00 1.00 1.00 1.00 1.00 1.00 1.00 1.00 1.00 1.00 1.00 1.00 1.00 1.00 1.00 1.00 1.00 1.00 1.00 1.00 1.00 1.00 1.00 1.00 1.00 1.00 1.00 1.00 1.00 1.00 1.00 1.00 1.00 1.00 1.00 1.00 1.00 1.00 1.00 1.00 1.00 1.00 1.00 1.00 1.00 1.00 1.00 1.00 1.00 1.00 1.00 1.00 1.00 1.00 1.00 1.00 1.00 1.00 1.00 1.00 1.00 1.00 1.00 1.00 1.00 1.00 1.00 1.00 1.00 1.00 1.00 1.00 1.00 1.00 1.00 1.00 1.00 1.00 1.00 1.00 1.00 1.00 1.00 1.00 1.00 1.00 1.00 1.00 1.00 1.00 1.00 1.00 1.00 1.00 1.00 1.00 1.00 1.00 1.00 1.00 1.00 1.00 1.00 1.00 1.00 1.00 1.00 1.00 1.00 1.00 1.00 1.00 1.00 1.00 1.00 1.00 1.00 1.00 1.00 1.00 1.00 1.00 1.00 1.00 1.00 1.00 1.00 1.00 1.00 1.00 1.00 1.00 1.00 1.00 1.00 1.00 1.00 1.00 1.00 1.00 1.00 1.00 1.00 1.00 1.00 1.00 1.00 1.00 1.00 1.00 1.00 1.00 1.00 1.00 1.00 1.00 1.00 1.00 1.00 1.00 1.00 1.00 1.00 1.00 1.00 1.00 1.00 1.00 1.00 1.00 1.00 1.00 1.00 1.00 1.00 1.00 1.00 1.00 1.00 1.00 1.00 1.00 1.00 1.00 1.00 1.00 1.00 1.00 1.00 1.00 1.00 1.00 1.00 1.00 1.00 1.00 1.00 1.00 1.00 1.00 1.00 1.00 1.00 1.00 1.00 1.00 1.00 1.00 1.00 1.00 1.00 1.00 1.00 1.00 1.00 1.00 1.00 1.00 1.00 1.00 1.00 1.00 1.00 1.00 1.00 1.00 1.00 1.00 1.00 1.00 1.00 1.00 1.00 1.00 1.00 1.00 1.00 1.00 1.00 1.00 1.00 1.00 1.00 1.00 1.00 1.00 1.00 1.00 1.00 1.00 1.00 1.00 1.00 1.00 1.00 1.00 1.00 1.00 1.00 1.00 1.00 1.00 1.00 1.00 1.00 1.00 1.00 1.00 1.00 1.00 1.00 1.00 1.00 1.00 1.00 1.00 1.00 1.00 1.00 1.00 1.00 1.00 1.00 1.00 1.00 1.00 1.00 1.00 1.00 1.00 1.00 1.00 1.00 1.00 1.00 1.00 1.00 1.00 1.00 1.00 1.00 1.00 1.00 1.00 1.00 1.00 1.00 1.00 1.00 1.00 1.00 1.00 1.00 1.00 1.00 1.00 1.00 1.00 1.00 1.00 1.00 1.00 1.00 1.00 1.00 1.00 1.00 1.00 1.00 1.00 1.00 1.00 1.00 1.00 1.00 1.00 1.00 1.00 1.00 1.00 1.00 1.00 1.00 1.00 1.00 1.00 1.00 1.00 1.00 1.00 1.00 1.00 1.00 1.00 1.00 1.00 1.00 1.00 1.00 1.00 1.00 1.00 1.00 1.00 1.00 1.00 1.00 1.00 1.00 1.00 1.00 1.00 1.00 1.00 1.00 1.00 1.00 1.00 1.00 1.00 1.00 1.00 1.00 1.00 1.00 1.00 1.00 1.00 1.00 1.00 1.00 1.00 1.00 1.00 1.00 1.00 1.00 1.00 1.00 1.00 1.00 1.00 1.00 1.00 1.00 1.00 1.00 1.00 1.00 1.00 1.00 1.00 1.00 1.00 1.00 1.00 1.00 1.00 1.00 1.00 1.00 1.00 1.00 1.00 1.00 1.00 1.00 1.00 1.00 1.00 1.00 1.00 1.00 1.00 1.00 1.00 1.00 1.00 1.00 1.00 1.00 1.00 1.00 1.00 1.00 1.00 1.00 1.00 1.00 1.00 1.00 1.00 1.00 1.00 1.00 1.00 1.00 1.00 1.00 1.00 1.00 1.00 1.00 1.00 1.00 1.00 1.00 1.00 1.00 1.00 1.00 1.00 1.00 1.00 1.00 1.00 1.00 1.00 1.00 1.00 1.00 1.00 1.00 1.00 1.00 1.00 1.00 1.00 1.00 1.00 1.00 1.00 1.00 1.00 1.00 1.00 1.00 1.00 1.00 1.00 1.00 1.00 1.00 1.00 1.00 1.00 1.00 1.00 1.00 1.00 1.00 1.00 1.00 1.00 1.00 1.00 1.00 1.00 1.00 1.00 1.00</beamAttenuationFactors>
				<commonCountingTime unit="seconds">0.60</commonCountingTime>
				<intensities unit="counts">12 9 15 17 9 8 17 4 15 5 3 9 9 8 9 12 10 6 4 7 8 10 9 4 8 8 7 8 8 4 7 11 9 6 5 8 12 5 10 7 5 3 8 6 8 8 1 5 12 12 11 10 10 10 5 5 10 10 7 8 6 6 7 6 8 6 3 7 9 8 9 8 5 10 12 8 9 9 6 9 6 8 12 9 9 6 5 8 11 6 8 9 7 7 6 6 14 8 6 3 7 13 9 10 10 3 2 7 7 7 10 11 10 12 7 11 8 6 9 7 5 5 6 11 9 10 7 8 8 5 10 8 9 6 8 4 9 6 9 8 4 9 7 6 5 12 5 8 11 7 6 3 4 10 7 8 6 6 8 4 7 4 7 5 9 8 6 5 8 6 5 13 7 6 4 8 5 8 10 6 11 6 5 5 8 5 4 9 5 3 5 11 13 12 3 5 4 14 10 5 5 7 6 7 6 1 4 8 7 0 6 9 9 7 7 7 8 6 6 9 2 9 7 8 12 6 16 7 4 6 5 4 10 5 8 6 5 6 4 4 4 8 5 5 7 5 7 9 7 6 4 4 3 11 8 11 15 6 7 5 8 4 9 12 2 5 6 5 8 6 8 6 4 5 10 5 9 2 5 4 5 8 4 5 11 8 8 4 8 6 11 5 6 6 5 5 8 7 3 4 6 3 5 6 4 6 11 8 6 7 7 7 5 7 4 5 4 9 8 3 3 5 5 6 7 9 7 5 4 2 7 6 6 7 4 8 5 7 4 6 1 4 6 3 11 5 3 4 7 5 6 8 4 4 11 4 7 4 6 6 10 4 4 9 4 10 11 7 4 5 6 8 5 4 5 7 4 9 3 4 9 6 6 7 10 4 6 7 4 2 3 4 4 7 3 11 4 9 7 10 12 6 85 566 161 14 9 4 5 6 8 7 2 3 8 13 5 8 5 5 3 8 6 5 5 7 6 3 5 4 4 6 2 6 7 5 6 8 4 5 8 2 7 4 4 3 3 3 2 4 5 8 9 6 3 6 5 7 9 6 4 5 3 4 4 2 4 5 8 7 3 6 4 4 3 6 5 4 8 4 6 2 5 2 5 3 4 1 6 8 4 10 4 2 1 8 6 4 2 6 4 2 1 4 4 1 6 6 5 9 3 2 4 5 2 5 5 7 6 7 0 7 5 4 3 2 5 5 4 6 4 2 4 3 3 3 5 4 3 2 4 2 5 6 5 1 9 3 5 7 3 6 4 4 4 4 2 7 7 3 3 2 10 5 5 1 6 2 4 7 3 6 5 5 3 5 6 4 5 6 2 6 2 8 5 6 5 7 3 2 2 7 4 4 3 2 5 9 6 5 10 7 7 6 4 5 4 7 4 4 1 8 4 6 3 7 4 4 6 1 4 4 9 6 5 5 8 6 2 1 5 5 3 10 5 3 4 2 6 4 5 4 7 4 6 4 8 1 9 6 5 10 4 6 6 6 11 0 8 6 6 7 5 5 3 7 3 3 8 10 5 8 8 5 4 6 7 6 9 2 4 6 4 6 9 4 6 7 5 9 7 10 4 9 8 7 2 9 10 6 4 7 2 10 5 3 5 14 5 12 4 10 12 11 9 12 11 13 4 14 20 16 19 27 10 21 20 21 15 27 24 24 36 36 46 42 53 61 75 81 89 119 128 135 159 177 160 197 195 211 218 216 243 237 230 212 212 175 208 143 136 153 116 124 101 103 64 69 61 60 56 37 30 39 30 21 21 27 22 20 14 14 17 15 8 12 6 12 9 13 10 8 12 8 7 11 5 6 15 10 10 10 6 7 6 8 5 9 9 7 7 11 7 6 5 2 10 6 6 10 5 4 7 3 5 5 5 6 8 8 4 2 2 5 5 7 4 6 3 6 4 6 4 4 6 5 6 5 2 5 5 4 6 1 3 7 1 4 7 3 2 3 6 2 4 2 3 7 3 8 2 6 6 5 3 4 4 6 5 0 4 8 1 4 2 2 6 2 4 8 2 4 1 2 5 2 6 4 3 7 6 5 3 4 3 5 0 5 4 5 2 5 3 6 4 2 3 6 4 5 3 1 3 4 6 2 2 4 4 3 5 4 3 2 4 3 8 5 5 5 5 5 0 6 3 6 5 6 5 4 3 2 4 0 7 4 2 5 3 4 6 3 3 4 1 6 4 3 5 7 3 6 2 5 5 1 4 0 4 5 5 4 4 2 5 3 3 2 7 4 2 2 3 4 3 6 8 4 4 3 2 2 5 2 2 3 3 7 4 6 6 2 6 3 5 6 2 6 3 4 5 5 2 5 3 3 7 0 2 3 5 2 2 5 5 7 5 2 2 6 7 7 6 8 1 9 8 6 8 6 5 7 7 6 7 10 9 8 8 16 9 14 9 10 14 15 18 12 19 18 14 15 25 21 28 14 15 28 22 21 13 19 19 21 11 4 17 12 9 8 11 7 7 7 4 8 4 1 3 10 7 7 10 3 4 6 3 9 6 5 4 4 6 10 5 8 6 4 2 1 6 6 6 4 3 2 1 7 2 4 3 2 3 3 5 7 5 1 3 3 0 5 1 1 3 5 7 5 3 8 2 2 5 5 4 1 2 1 3 3 2 3 5 4 4 2 4 4 4 3 3 7 1 3 5 4 4 2 1 4 2 6 6 2 8 2 9 4 8 3 3 4 4 5 1 3 2 2 2 1 4 4 7 3 2 3 2 4 5 4 2 6 7 6 8 1 1 2 5 3 1 2 6 4 0 4 4 3 3 5 3 4 2 1 5 1 1 1 4 6 6 3 3 5 2 1 2 5 2 3 3 2 3 0 2 3 3 4 5 3 1 2 4 5 3 5 3 3 2 3 2 1 4 3 2 4 0 3 6 3 3 5 7 4 1 2 9 4 3 0 3 2 0 4 2 2 1 3 4 5 1 3 4 2 5 2 0 3 3 2 2 3 2 2 3 5 0 5 3 5 2 3 2 4 3 2 7 2 6 4 6 3 0 3 1 4 4 2 1 3 3 0 3 6 3 1 2 2 6 3 5 4 1 1 2 2 3 3 2 3 4 4 6 2 5 2 3 0 1 2 5 7 1 3 1 4 5 3 3 3 4 3 3 3 1 4 6 2 2 2 1 4 5 4 2 1 7 4 4 5 1 2 0 3 5 3 2 2 4 3 3 5 1 0 6 1 5 3 0 1 7 2 5 4 5 3 2 5 1 1 0 3 4 2 3 3 3 4 3 2 2 3 2 4 1 0 1 2 6 0 3 4 2 2 8 2 5 6 2 3 2 0 2 1 1 2 2 0 3 3 4 0 3 3 0 0 7 1 3 4 3 4 2 4 4 5 2 4 2 6 4 2 1 4 2 4 1 4 2 4 1 6 4 2 2 4 4 3 6 4 2 2 3 1 3 1 3 3 3 2 1 4 1 3 0 2 4 2 4 7 2 4 2 4 2 2 1 3 7 1 2 3 2 0 2 0 1 2 3 3 5 0 4 3 2 2 3 4 2 7 3 2 2 1 1 3 1 3 4 2 3 3 3 6 1 4 5 7 0 2 6 4 1 1 4 5 3 0 3 4 2 1 4 1 2 2 4 2 4 2 1 1 4 3 3 6 5 1 3 3 1 3 3 2 1 4 8 4 1 3 0 1 4 2 4 4 0 3 3 1 1 3 1 4 3 2 1 3 1 2 3 6 1 2 2 3 5 2 3 7 5 0 2 3 5 2 2 1 3 3 1 1 2 2 6 1 5 2 2 2 3 4 1 6 5 2 1 4 0 3 2 3 1 3 1 2 4 3 2 2 1 5 4 1 2 3 2 5 2 6 5 2 7 3 5 2 6 4 3 5 2 4 5 3 2 4 1 4 5 3 2 2 3 2 6 4 0 3 2 1 0 4 4 1 2 3 3 2 3 4 1 3 1 3 3 1 2 2 4 3 2 1 3 1 3 7 3 8 3 0 4 3 3 3 2 1 3 3 5 1 4 5 5 3 2 2 5 4 2 3 2 0 4 3 1 1 2 4 4 3 3 1 2 5 3 5 4 2 3 2 3 4 2 3 2 2 5 6 2 2 3 0 2 4 2 4 3 3 3 1 1 5 1 4 2 4 2 5 2 2 2 3 5 2 1 3 4 4 3 5 5 2 5 5 1 3 1 1 4 5 7 3 2 3 0 4 2 8 3 1 2 2 5 3 3 5 3 7 1 3 4 0 4 4 3 1 3 3 3 2 6 4 8 0 3 2 3 4 0 3 1 4 5 2 2 3 8 5 3 1 4 1 3 2 10 4 2 4 4 2 2 2 2 4 6 7 3 3 3 1 3 1 7 5 4 2 2 4 5 3 4 6 3 2 4 3 11 6 5 3 1 8 3 5 1 2 3 6 1 5 3 5 2 3 2 4 4 4 4 3 2 6 7 5 4 6 4 7 3 3 3 1 7 1 3 1 5 5 2 9 2 6 5 5 2 3 4 3 4 9 8 7 4 2 4 5 2 3 4 3 2 7 0 5 7 6 4 2 8 5 7 5 4 6 6 4 5 2 5 4 5 3 3 2 2 2 6 1 3 6 3 4 6 4 7 4 2 5 5 5 6 4 8 7 9 6 4 4 5 8 4 4 4 7 4 7 4 4 12 3 5 6 8 4 9 5 8 9 7 5 16 3 8 7 10 8 10 9 5 8 5 9 11 6 6 10 11 18 15 9 9 6 7 8 9 13 13 10 13 8 16 7 7 8 8 9 15 10 8 8 5 11 8 12 10 6 12 9 14 16 8 12 10 10 16 22 6 16 9 21 14 14 17 20 9 14 20 23 12 14 16 23 23 18 22 20 18 22 17 16 32 18 32 29 20 22 25 32 34 41 33 30 33 32 26 37 45 36 32 40 41 45 51 40 42 51 50 63 53 61 68 67 73 86 84 102 84 102 90 118 101 118 127 149 135 191 172 175 192 240 238 288 292 324 357 415 461 562 660 1113 5629 98469 288129 154066 72101 5948 1105 736 413 316 224 193 172 148 145 109 107 106 79 82 83 62 57 58 62 66 44 60 50 43 32 44 38 42 44 45 35 33 33 32 31 33 26 34 30 20 21 25 19 25 26 17 27 26 17 22 19 27 25 17 23 15 14 17 17 13 15 16 12 25 11 13 12 14 17 19 16 9 18 18 11 13 9 15 15 13 13 14 11 12 10 10 17 18 10 19 7 11 11 8 8 18 14 5 10 13 13 13 3 8 6 9 9 8 8 7 8 6 8 5 3 14 8 8 12 6 5 7 5 3 6 10 5 4 2 8 7 9 3 10 6 5 10 4 3 9 5 5 8 10 6 6 5 4 8 7 3 5 8 6 2 3 6 4 6 3 8 7 6 6 5 7 3 2 6 5 6 9 7 0 8 5 3 3 4 4 4 6 4 1 4 10 7 7 1 0 6 1 2 5 6 6 3 6 6 0 2 6 2 1 5 6 3 2 5 6 7 7 6 4 5 6 7 3 5 5 6 3 8 4 5 3 2 3 5 4 2 5 1 2 1 5 6 4 4 5 1 4 1 5 2 4 4 3 5 0 3 1 6 4 0 5 3 4 7 1 5 6 1 6 5 6 0 3 4 2 5 5 2 2 4 2 0 4 4 4 3 3 4</intensities>
			</dataPoints>
		</scan>
	</xrdMeasurement>
</xrdMeasurements>